Workbook

Sheet Instructions
A1: UMC-BCK — Feature Migration Tracker
A2: Every dashboard, tab, and feature that exists in the working HTML prototype, tracked against real migration progress into Supabase and React.
A5: WHY THIS EXISTS
A6: This tracker exists specifically to prevent what happened during the CHS migration — features that were real and working in the
A7: prototype getting treated as "placeholders" and quietly left behind because nobody had written down, unambiguously, that they
A8: were real. Every row below was pulled directly from the actual HTML source code, not from memory.
A10: HOW TO USE THIS DURING THE MIGRATION
A11: 1. Before starting work on any feature, find it in this tracker and confirm its "HTML Prototype" status is Done — if it's not
A12: listed here at all, something was missed in this audit and should be added, not skipped.
A13: 2. As each feature's database structure is built in Supabase, update its "Supabase Schema" status.
A14: 3. As each feature is rebuilt in the React frontend, update its "React Frontend" status.
A15: 4. A feature is NOT considered migrated until all three columns say Done. Partial means real work started but the feature is
... A30: This is a living document. It should be more current than anyone's memory of the project, including the AI's.

Sheet NEEDS YOUR ATTENTION
A1: ⚠ NEEDS YOUR ATTENTION — set aside, not to be treated until the full migration is genuinely done
A2: Kept deliberately separate per explicit instruction, so nothing here gets lost, mixed into build work, or forgotten while attention is on something else.
A4: # | B4: Item | C4: What's needed from you | D4: Where it came from
A5: 1 | B5: ✅ RESOLVED — PWA manifest was never actually broken, see Supabase Progress sheet | C5: Real root cause found and fixed: Netlify's catch-all redirect was serving index.html for every request, including /manifest.json — the manifest file itself was always correct. | D5: PWA/deployment work, early session
A6: 2 | B6: Voice-to-text parsing (Sales Register) is deployed but cannot function yet | C6: A real ANTHROPIC_API_KEY needs to be set as a Supabase Edge Function secret — same setup as the Paystack key, never touches this codebase | D6: Feature #144 (Sales Register)
A7: 3 | B7: 7 Bills & Services categories (Water, JAMB, NABTEB, School Fees, NIN, Road Transport, Flights/Hotels) | C7: Which VTU/billing provider to actually integrate with — nothing to build until this is chosen | D7: Bills & Services hub, flagged repeatedly across the session
A8: 4 | B8: Bills & Services 2-4% platform margin | C8: Downstream of the provider decision above — no real automated settlement exists yet to apply a margin to | D8: Handover-document audit, Section 14
A9: 5 | B9: Pure Gold & Precious Metals — no seed data | C9: Real seller and product data is needed — this was never invented, per the standing discipline against fabricating data | D9: Flagged since early tracker reconciliation
A10: 6 | B10: Two separate Netlify deployments exist (different URLs) | C10: A decision on which one is canonical, and whether to consolidate into one | D10: PWA/deployment work, early session
A11: 7 | B11: "One or two other suggestions" — mentioned but not yet detailed | C11: Your own description of what these are, once migration work is complete | D11: Raised directly in this conversation
A12: 8 | B12: Login method redesign (phone + 6-digit PIN, with biometric fast-path) | C12: Real analysis and recommendation given, matching your sister app's PIN convention — but this fundamentally changes how Supabase Auth is used platform-wide and needs your explicit confirmation before being built, not assumed | D12: Login/auth discussion, this session
A13: 9 | B13: Delivery Agent 'Face verified' badge — needs a real biometric KYC provider | C13: The real source shows this as a genuine liveness/face-match verification, not just an ID upload. Requires a real third-party biometric KYC service (e.g. Smile Identity, Youverify) and a provider decision — not something to fake with a cosmetic badge | D13: Real-source parity audit, Delivery section
A14: 10 | B14: Buyer never actively confirms delivery — a real, larger architectural gap found while building ratings | C14: The handover document explicitly requires the buyer to tap 'Confirm received' or 'Raise dispute' before the agent can leave — but the current build has the AGENT calling mark_order_delivered directly, with no real buyer-side confirmation gate at all. This is a real, separate redesign of the delivery-confirmation flow, not something to rush alongside the ratings feature built this round | D14: Real-source parity audit, Delivery Performance section
A15: 11 | B15: Proxy pickup — real encrypted QR ticket system not yet built | C15: 'Proxy pickup' exists as a selectable delivery option, but the real source requires a genuine encrypted/signed QR ticket tied to the order, validated at the pickup point, for someone other than the buyer to collect. Currently just a label with no real ticket-generation or validation behind it | D15: Real-source parity audit, Buyer checkout section

Sheet REAL SOURCE PARITY CHECKLIST
A1: REAL SOURCE PARITY CHECKLIST — every screen, checked against the actual original index.html
A2: Source of truth: /mnt/user-data/uploads/index.html (7,106 real lines) + UMC_BCK_Feature_Handover_Notes.md. Not guessed, not reconstructed from memory.
A4: Role | B4: Real Screen | C4: Status | D4: What was checked / found | E4: Real fix applied
A5: Buyer | B5: home | C5: Done | D5: Full real productCatalogue restored — 201 real items across 24 categories, found directly in source and inserted into master_catalog_items. Category rail, markets near you, search scope all real
A6: Buyer | B6: cart | C6: Done | D6: Scroll-to-accept terms gate verified real; hardcoded terms_accepted:true bug found and fixed to pass real state | E6: Fixed
A7: Buyer | B7: checkout | C7: Done | D7: Weight/urgency surcharges built last round. This round: real tiered store-pickup pricing added — free for 1 store, real fee for 2-5, higher for 6+. One real design decision: since each seller checks out as a separate transaction, the fee is charged once per session (the first pickup checkout) via sessionStorage rather than re-charged on every subsequent pickup, since it covers one real trip, not per-store. Caught and fixed a real bug in the same pass: the fee params block was silently overriding the calculated pickup fee back to zero. Still open: real encrypted QR ticket for Proxy pickup, named on attention sheet
A8: Buyer | B8: terms / terms-full | C8: Done | D8: Real scroll-tracking mechanism confirmed matching source exactly
A9: Buyer | B9: mklist (My List) | C9: Done | D9: renderMarketList() confirmed functionally identical to what's already built as Price Watch/Market List — bookmark + target price tracking, both real
A10: Buyer | B10: bills | C10: Done | D10: 4 of 6 real tabs already matched (Airtime, Data, Bills, Education combine cleanly with existing categories). Travel and Instalment/BNPL confirmed to be unbuilt stub buttons in the original source itself — nothing to restore honestly, not invented. Real network dropdown (MTN/Glo/Airtel/9mobile) added for airtime/data, replacing free text. Caught and fixed a real bug in the same pass: a new useEffect referenced setProvider before its declaration, which would have thrown at runtime
A11: Buyer | B11: profile | C11: Done | D11: Rebuilt to match real source: personal info, delivery addresses, favourite sellers, account settings links
A12: Buyer | B12: success | C12: Done | D12: Was a small inline banner; real source has a genuine dedicated confirmation screen. Rebuilt fully — real checkmark, real reassurance message, order reference, and Back to marketplace now genuinely navigates rather than just clearing local state
A13: Seller | B13: dashboard | C13: Partial | D13: Real gap found: was showing all-time totals only, not Sales today/This week as source requires. Fixed with real date-filtered queries plus real Go to Upload/View orders shortcuts. Still open: Seller ID + QR code section (found in source, not yet built anywhere)
A14: Seller | B14: upload | C14: Done | D14: Real category taxonomy corrected — the real source has more granular categories (separate Fashion sub-types, separate alcohol/beverage categories, Books & stationery, Airtime & data) than my earlier restoration used. Fixed in both seller and buyer category lists. Real brand dropdown found missing entirely — category_brands existed as real seed data but nothing queried it; wired in fully, including a real products.brand column that didn't exist to save the value into
A15: Seller | B15: stock | C15: Done | D15: Real gap found against handover doc's own language: Available/Sold out/Restocked required, attendant must never set this. sold_out existed, restocked did not. Added restocked enum value + set_product_stock_status() with real owner-only check (not just UI hiding)
A16: Seller | B16: orders | C16: Done | D16: Confirmed already real and matching — confirm_order()/reject_order() with genuine pending-count UI, verified directly against source
A17: Seller | B17: register | C17: Done | D17: Sales Register built extensively this session — barcode, credit sales, offline queue, voice
A18: Seller | B18: attendant | C18: Done | D18: Real stock/sale/request features already matched core structure. Two real precise gaps found and fixed: real 'suggested restock quantity' field added (was previously a bare flag), and real 'deposit paid' field added to credit requests, flowing through to the receivable's real outstanding balance. A real function-overload bug was caught and fixed in the same round: CREATE OR REPLACE with a new trailing parameter silently reset anon/public revokes on 2 functions — caught by direct verification, not assumed safe
... A22: Director | B22: attendants | C22: Done | D22: Assignment, access-code generation, approvals queue all built
A23: Delivery | B23: register | C23: Not yet checked
A24: Delivery | B24: orders | C24: Done | D24: Confirmed already real and matching — confirm_order()/reject_order() with genuine pending-count UI, verified directly against source
A25: Delivery | B25: earnings | C25: Done | D25: Was one flat all-time number; real source needs 4 real metrics (Today, Waiting time bonus, This week, Wallet balance). Found the real waiting-bonus data already existed as wallet_transactions with reference_type='waiting_fine' — nothing surfaced it. Fixed with genuine date-filtered queries, no invented numbers
A26: Delivery | B26: performance | C26: Done | D26: A real, entirely new feature found missing platform-wide: buyer ratings for delivery agents. Built completely — real delivery_ratings table, real rate_delivery_agent() (one per order, genuine buyer only, genuinely delivered order only), real live-computed aggregate (average rating, completion rate, on-time rate from real sla_deadline comparison — no stored average that could drift). Real rating prompt added to buyer's MyOrders for delivered, unrated orders
A27: Delivery | B27: company | C27: Done | D27: Was only capturing company_name — real source requires genuine legal identity: CAC number, TIN, verifiable address, state + year of incorporation, real CAC certificate upload, accountable director/signatory. All added with a real private storage bucket
A28: Canteen | B28: register | C28: Not yet checked
A29: Canteen | B29: order | C29: Partial | D29: Category taxonomy + dish quick-pick restored; multi-soup/multi-protein selector pattern not yet confirmed built
A30: Canteen | B30: group | C30: Done | D30: Found genuinely bigger than what existed — contributor_name was just a text label, not a real shareable group-order system. Built completely: real short shareable code, real join-by-code with deadline enforcement, real order tagging via a new group_order_id — only the initiator's checkout carries the real delivery fee, avoiding fragile split-fee math needing a final headcount before checkout. THIRD occurrence of the CREATE OR REPLACE overload/revoke bug caught in this same round (place_order and checkout_cart both), both verified and fixed directly rather than assumed safe
A31: Canteen | B31: checkout | C31: Done | D31: Weight/urgency surcharges built last round. This round: real tiered store-pickup pricing added — free for 1 store, real fee for 2-5, higher for 6+. One real design decision: since each seller checks out as a separate transaction, the fee is charged once per session (the first pickup checkout) via sessionStorage rather than re-charged on every subsequent pickup, since it covers one real trip, not per-store. Caught and fixed a real bug in the same pass: the fee params block was silently overriding the calculated pickup fee back to zero. Still open: real encrypted QR ticket for Proxy pickup, named on attention sheet
A32: Canteen | B32: track | C32: Done | D32: Real, more granular 4-stage tracker found — a genuine 'preparing' status with an estimated ready time, sitting between confirmed and assigned, that didn't exist in the generic order lifecycle. Added the real enum value, a real seller-only transition function, and a real visual tracker on the buyer's receipt derived from genuine order/assignment state, not a simulated progress bar. Seller-side 'Mark as preparing' button added to Incoming Orders
A33: Used Items | B33: browse | C33: Done | D33: Real, significant gap found: no category field existed anywhere — despite the handover document's own Section 12 explicitly naming category as a required field. Added the real column, the real 6-category taxonomy from the source (Electronics, Furniture, Fashion, Vehicles, Instruments, Other), and a real filter pill row on browse
A34: Used Items | B34: list | C34: Done | D34: Real category dropdown added to the listing form, wired into the actual insert — was previously entirely absent
A35: Used Items | B35: free | C35: Done | D35: Sadaqah framing confirmed present

Sheet Summary
A1: Migration Progress Summary
A2: Counts below are live formulas against the Feature Tracker sheet — they recalculate automatically as statuses are updated.
A4: Layer | B4: Done | C4: Partial | D4: Not started | E4: Total
A5: HTML Prototype | B5: =COUNTIF('Feature Tracker'!F3:F147,"Done") -> 144 | C5: =COUNTIF('Feature Tracker'!F3:F147,"Partial") -> 0 | D5: =COUNTIF('Feature Tracker'!F3:F147,"Not started") -> 1 | E5: =SUM(B5:D5) -> 145
A6: Supabase Schema | B6: =COUNTIF('Feature Tracker'!G3:G147,"Done") -> 127 | C6: =COUNTIF('Feature Tracker'!G3:G147,"Partial") -> 18 | D6: =COUNTIF('Feature Tracker'!G3:G147,"Not started") -> 0 | E6: =SUM(B6:D6) -> 145
A7: React Frontend | B7: =COUNTIF('Feature Tracker'!H3:H147,"Done") -> 136 | C7: =COUNTIF('Feature Tracker'!H3:H147,"Partial") -> 2 | D7: =COUNTIF('Feature Tracker'!H3:H147,"Not started") -> 7 | E7: =SUM(B7:D7) -> 145
A9: Total features tracked: | B9: =COUNTA('Feature Tracker'!D3:D147) -> 145
A11: By Area
A12: Area | B12: Total Features | C12: Supabase — Done | D12: Supabase — Partial | E12: Supabase — Not started
A13: Buyer Marketplace | B13: =COUNTIF('Feature Tracker'!$B$3:$B$145,A13) -> 25 | C13: =COUNTIFS('Feature Tracker'!$B$3:$B$145,A13,'Feature Tracker'!$G$3:$G$145,"Done") -> 25 | D13: =COUNTIFS('Feature Tracker'!$B$3:$B$145,A13,'Feature Tracker'!$G$3:$G$145,"Partial") -> 0 | E13: =COUNTIFS('Feature Tracker'!$B$3:$B$145,A13,'Feature Tracker'!$G$3:$G$145,"Not started") -> 0
A14: Seller Dashboard | B14: =COUNTIF('Feature Tracker'!$B$3:$B$145,A14) -> 16 | C14: =COUNTIFS('Feature Tracker'!$B$3:$B$145,A14,'Feature Tracker'!$G$3:$G$145,"Done") -> 16 | D14: =COUNTIFS('Feature Tracker'!$B$3:$B$145,A14,'Feature Tracker'!$G$3:$G$145,"Partial") -> 0 | E14: =COUNTIFS('Feature Tracker'!$B$3:$B$145,A14,'Feature Tracker'!$G$3:$G$145,"Not started") -> 0
A15: Canteen & Fast Food | B15: =COUNTIF('Feature Tracker'!$B$3:$B$145,A15) -> 9 | C15: =COUNTIFS('Feature Tracker'!$B$3:$B$145,A15,'Feature Tracker'!$G$3:$G$145,"Done") -> 9 | D15: =COUNTIFS('Feature Tracker'!$B$3:$B$145,A15,'Feature Tracker'!$G$3:$G$145,"Partial") -> 0 | E15: =COUNTIFS('Feature Tracker'!$B$3:$B$145,A15,'Feature Tracker'!$G$3:$G$145,"Not started") -> 0
A16: Delivery Agent | B16: =COUNTIF('Feature Tracker'!$B$3:$B$145,A16) -> 9 | C16: =COUNTIFS('Feature Tracker'!$B$3:$B$145,A16,'Feature Tracker'!$G$3:$G$145,"Done") -> 9 | D16: =COUNTIFS('Feature Tracker'!$B$3:$B$145,A16,'Feature Tracker'!$G$3:$G$145,"Partial") -> 0 | E16: =COUNTIFS('Feature Tracker'!$B$3:$B$145,A16,'Feature Tracker'!$G$3:$G$145,"Not started") -> 0
A17: Director Dashboard | B17: =COUNTIF('Feature Tracker'!$B$3:$B$145,A17) -> 4 | C17: =COUNTIFS('Feature Tracker'!$B$3:$B$145,A17,'Feature Tracker'!$G$3:$G$145,"Done") -> 4 | D17: =COUNTIFS('Feature Tracker'!$B$3:$B$145,A17,'Feature Tracker'!$G$3:$G$145,"Partial") -> 0 | E17: =COUNTIFS('Feature Tracker'!$B$3:$B$145,A17,'Feature Tracker'!$G$3:$G$145,"Not started") -> 0
A18: Bills & Services | B18: =COUNTIF('Feature Tracker'!$B$3:$B$145,A18) -> 18 | C18: =COUNTIFS('Feature Tracker'!$B$3:$B$145,A18,'Feature Tracker'!$G$3:$G$145,"Done") -> 1 | D18: =COUNTIFS('Feature Tracker'!$B$3:$B$145,A18,'Feature Tracker'!$G$3:$G$145,"Partial") -> 17 | E18: =COUNTIFS('Feature Tracker'!$B$3:$B$145,A18,'Feature Tracker'!$G$3:$G$145,"Not started") -> 0
A19: Phones & Tech Hub | B19: =COUNTIF('Feature Tracker'!$B$3:$B$145,A19) -> 17 | C19: =COUNTIFS('Feature Tracker'!$B$3:$B$145,A19,'Feature Tracker'!$G$3:$G$145,"Done") -> 17 | D19: =COUNTIFS('Feature Tracker'!$B$3:$B$145,A19,'Feature Tracker'!$G$3:$G$145,"Partial") -> 0 | E19: =COUNTIFS('Feature Tracker'!$B$3:$B$145,A19,'Feature Tracker'!$G$3:$G$145,"Not started") -> 0
A20: Gold & Jewelry Hub | B20: =COUNTIF('Feature Tracker'!$B$3:$B$145,A20) -> 7 | C20: =COUNTIFS('Feature Tracker'!$B$3:$B$145,A20,'Feature Tracker'!$G$3:$G$145,"Done") -> 6 | D20: =COUNTIFS('Feature Tracker'!$B$3:$B$145,A20,'Feature Tracker'!$G$3:$G$145,"Partial") -> 1 | E20: =COUNTIFS('Feature Tracker'!$B$3:$B$145,A20,'Feature Tracker'!$G$3:$G$145,"Not started") -> 0
A21: Automobile Hub | B21: =COUNTIF('Feature Tracker'!$B$3:$B$145,A21) -> 7 | C21: =COUNTIFS('Feature Tracker'!$B$3:$B$145,A21,'Feature Tracker'!$G$3:$G$145,"Done") -> 7 | D21: =COUNTIFS('Feature Tracker'!$B$3:$B$145,A21,'Feature Tracker'!$G$3:$G$145,"Partial") -> 0 | E21: =COUNTIFS('Feature Tracker'!$B$3:$B$145,A21,'Feature Tracker'!$G$3:$G$145,"Not started") -> 0
A22: Pharma & Medical Hub | B22: =COUNTIF('Feature Tracker'!$B$3:$B$145,A22) -> 10 | C22: =COUNTIFS('Feature Tracker'!$B$3:$B$145,A22,'Feature Tracker'!$G$3:$G$145,"Done") -> 10 | D22: =COUNTIFS('Feature Tracker'!$B$3:$B$145,A22,'Feature Tracker'!$G$3:$G$145,"Partial") -> 0 | E22: =COUNTIFS('Feature Tracker'!$B$3:$B$145,A22,'Feature Tracker'!$G$3:$G$145,"Not started") -> 0
A23: Admin Control Room | B23: =COUNTIF('Feature Tracker'!$B$3:$B$145,A23) -> 11 | C23: =COUNTIFS('Feature Tracker'!$B$3:$B$145,A23,'Feature Tracker'!$G$3:$G$145,"Done") -> 11 | D23: =COUNTIFS('Feature Tracker'!$B$3:$B$145,A23,'Feature Tracker'!$G$3:$G$145,"Partial") -> 0 | E23: =COUNTIFS('Feature Tracker'!$B$3:$B$145,A23,'Feature Tracker'!$G$3:$G$145,"Not started") -> 0
A24: Used Items (Secondhand) | B24: =COUNTIF('Feature Tracker'!$B$3:$B$145,A24) -> 4 | C24: =COUNTIFS('Feature Tracker'!$B$3:$B$145,A24,'Feature Tracker'!$G$3:$G$145,"Done") -> 4 | D24: =COUNTIFS('Feature Tracker'!$B$3:$B$145,A24,'Feature Tracker'!$G$3:$G$145,"Partial") -> 0 | E24: =COUNTIFS('Feature Tracker'!$B$3:$B$145,A24,'Feature Tracker'!$G$3:$G$145,"Not started") -> 0
... A26: Platform-wide | B26: =COUNTIF('Feature Tracker'!$B$3:$B$145,A26) -> 4 | C26: =COUNTIFS('Feature Tracker'!$B$3:$B$145,A26,'Feature Tracker'!$G$3:$G$145,"Done") -> 4 | D26: =COUNTIFS('Feature Tracker'!$B$3:$B$145,A26,'Feature Tracker'!$G$3:$G$145,"Partial") -> 0 | E26: =COUNTIFS('Feature Tracker'!$B$3:$B$145,A26,'Feature Tracker'!$G$3:$G$145,"Not started") -> 0

Sheet Feature Tracker
A1: UMC-BCK Feature Migration Tracker — every row pulled from the live HTML prototype source code
A2: # | B2: Area | C2: Screen / Tab | D2: Feature | E2: Description | F2: HTML Prototype | G2: Supabase Schema | H2: React Frontend | I2: Notes
A3: 1 | B3: Buyer Marketplace | C3: Home | D3: Multi-store browse | E3: Browse products pooled across every registered seller in one feed | F3: Done | G3: Done | H3: Done | I3: products RLS (status='live') + sellers.is_open already pool every store into one queryable feed — no separate schema needed | React: Marketplace.jsx queries real live products, respects existing RLS
A4: 2 | B4: Buyer Marketplace | C4: Home | D4: Product search | E4: Search across the full marketplace catalogue | F4: Done | G4: Done | H4: Done | I4: search_products() — real Postgres full-text search with a generated tsvector + GIN index, not "the frontend filters a list" | React: Real search bar wired into HubBrowse (all six hubs), calling search_products() directly — deliberately platform-wide, not hub-scoped
A5: 3 | B5: Buyer Marketplace | C5: Home | D5: Compare prices | E5: Compare the same/similar item across multiple sellers | F5: Done | G5: Done | H5: Done | I5: | React: Compare Prices on Product Detail — uses the exact same search_products() every hub search bar calls, no separate invented matching logic | Supabase column corrected — Reuses search_products() — no separate backend needed, real full-text search
A6: 4 | B6: Buyer Marketplace | C6: Home | D6: Product variants | E6: Size/brand/price option picker on a product card | F6: Done | G6: Done | H6: Done | I6: product_variants — built during the Canteen session, applies identically here | React: ProductDetail.jsx — real variant selection, computes actual line total
A7: 5 | B7: Buyer Marketplace | C7: Home | D7: Pepper variety selector | E7: Single product card with a variety dropdown, not separate listings per pepper type | F7: Done | G7: Done | H7: Done | I7: product_variants — pepper varieties are just variants of one product card, not separate listings | React: product_variants already renders as a picker in ProductDetail — pepper varieties are just variants of one product, no separate UI needed
A8: 6 | B8: Buyer Marketplace | C8: Home | D8: Vegetable variety selector | E8: Same pattern as pepper, for vegetables | F8: Done | G8: Done | H8: Done | I8: product_variants — same mechanism as pepper | React: Same mechanism as pepper
A9: 7 | B9: Buyer Marketplace | C9: Home | D9: Beverage variety selector | E9: Same pattern for beverages | F9: Done | G9: Done | H9: Done | I9: product_variants — same mechanism | React: Same mechanism
A10: 8 | B10: Buyer Marketplace | C10: Home | D10: Fashion size/colour chips | E10: Size and colour selection chips for fashion/footwear/baby categories | F10: Done | G10: Done | H10: Done | I10: product_variants — a size/colour combination is just another variant | React: Same mechanism — size/colour combinations are variants
A11: 9 | B11: Buyer Marketplace | C11: Home | D11: Stock status display | E11: Available / Sold out / Restocked badge on listings | F11: Done | G11: Done | H11: Done | I11: products.status enum (pending_review/live/rejected/sold_out/discontinued) already covers this | React: ProductDetail now displays real stock_quantity, with out-of-stock correctly disabling Add to cart
A12: 10 | B12: Buyer Marketplace | C12: Home | D12: New/Fairly-Used condition toggle | E12: Condition badge for Electronics, Fittings & Lighting, Computers, Phones, Automobile parts categories | F12: Done | G12: Done | H12: Done | I12: products.condition enum already covers this | React: ProductDetail now displays real product.condition
A13: 11 | B13: Buyer Marketplace | C13: Home | D13: Bulk pricing display | E13: Retail price vs. bulk price/minimum-quantity break shown on a listing | F13: Done | G13: Done | H13: Done | I13: product_variants already supports this — 'Retail 1kg' and 'Bulk 10kg bag' as two variants with different prices is the same mechanism as any other variant pair | React: product_variants already covers bulk-vs-retail pricing as variant pairs
A14: 12 | B14: Buyer Marketplace | C14: Home | D14: "Can't find it" demand registration | E14: General marketplace version of the demand-broadcast pattern | F14: Done | G14: Done | H14: Done | I14: demand_requests — built generically, works identically here with hub='general_marketplace' | React: DemandRequest.jsx — shared component, wired into HubBrowse once, covering all six hubs in a single edit
... A147: 145 | B147: Seller Dashboard | C147: Attendant workflow | D147: Credit-sale and restock approval requests | E147: Real gap confirmed absent from the live database (zero matching tables) while auditing the formal handover document on 2026-08-04. Originally specified: attendants can submit a credit-sale approval request or a restock request; sellers/directors approve or reject. Attendants must never have write access to price or product fields — this part IS correctly enforced today via real RLS. What's missing is the actual credit_requests / restock_requests tables and workflow. Connects directly to the credit-sales piece of the new Sales Register proposal (Feature #144) — not purely new scope, partly a rediscovery of an old, never-built spec item. | F147: Done | G147: Done | H147: Done | I147: Found during the section-by-section handover-document audit requested this session. Real, specific, and should likely be folded into Feature #144's build rather than built twice separately. | Restock half built and real: submit_restock_request(), resolve_restock_request() (genuinely updates stock_quantity when marked restocked), real seller-facing queue, real attendant-facing flag button. Credit-request half deliberately NOT rebuilt as a separate approval gate — the newer, more detailed Sales Register conversation with the user produced a more direct design (attendants record credit sales directly via record_credit_sale(), tracked through real receivables) which may have superseded the older spec's approval-gated concept. Flagged to the user rather than guessed | Approval gate added per explicit direction: record_credit_sale() no longer accepts an attendant caller — only store owner or admin. An attendant's only path is submit_credit_sale_request() -> owner reviews via resolve_credit_sale_request(), which genuinely calls record_credit_sale() on approval (same real inventory decrement and receivable, one settlement path not two). Frontend detects real ownership and branches the credit flow accordingly, with clear copy telling an attendant their sale needs approval before it's recorded

Sheet Supabase Progress (Real)
A1: What Actually Exists in the Real Supabase Project — Right Now
A2: Project: UMC-BCK · Region: eu-central-1 · This is ground truth verified directly against the live database, not a plan.
A3: Item | B3: What it does | C3: Notes
A4: IDENTITY & ACCESS CONTROL
A5: profiles | B5: One row per real Supabase Auth user, auto-created on signup via trigger | C5: Never insert directly — the trigger owns this
A6: get_user_role() | B6: Security-definer helper so RLS policies can check role without recursive lookups | C6: Deliberately public — RLS policies require this
A7: sellers | B7: Store registration: tier, CAC, LGA, market, is_open, verification_status, instalment_opt_in | C7: Buyer-facing browse must filter is_open at query time
A8: attendants | B8: Linked to a store, access code, RLS-enforced view-only access | C8: Cannot see cost price or margins — enforced at the database level, not just hidden in the UI
A9: MONEY — WALLETS & LEDGER
A10: wallets | B10: One per user, auto-created, balance is a read-only cache | C10: Never write balance directly
A11: wallet_transactions | B11: Append-only ledger: credit / debit / hold / release | C11: This is the actual source of truth, not the cached balance
A12: wallet_topup_requests | B12: Tracks bank-transfer top-up claims separately from the actual credit | C12: Confirming a request is what triggers the real credit
A13: 6 wallet functions | B13: credit_wallet, place_wallet_hold, finalize_wallet_hold, release_wallet_hold, request_wallet_topup, confirm_wallet_topup | C13: The only sanctioned way any money moves — no direct table writes, not even by the account owner
A14: PRODUCTS
A15: products | B15: Shared fields: seller, category, name, price, condition, status, stock, instalment_eligible | C15: product_type decides which detail table applies
A16: product_vehicle_details | B16: VIN, mileage, year, body type, transmission, fuel, duty status, accident history | C16: Seller-declared, matches how Verify works everywhere — not independently verified
A17: product_precious_metal_details | B17: Karat + weight, for actual gold/silver items only | C17: Deliberately separate from fashion/costume jewelry
A18: product_bulk_medication_details | B18: Carton size, half-carton price, full-carton price | C18: full_carton_price > half_carton_price is a real database constraint — cannot be violated even by a bug in application code
A19: Detail-table integrity check | B19: A vehicle/precious-metal/bulk-medication product without its matching detail row is structurally impossible to create | C19: Deferred constraint trigger, checked at commit
A20: ORDERS
A21: orders | B21: Buyer, seller, status, subtotal, delivery fee, total, is_instalment flag | C21: Every status transition goes through a function, never a direct update
A22: order_items | B22: Line items, priced at the moment of purchase | C22: Product price changes later never retroactively change what the buyer agreed to pay
A23: order_payments | B23: Every individual payment against an order | C23: A regular order has one row; an instalment order has one per payment
A24: order_instalment_details | B24: Deposit, remaining balance, refund-tier dates | C24: Enforces deposit < total as a real cross-table check
A25: place_order() | B25: Creates an order, prices every item from the real products table, places the correct wallet hold | C25: Never trusts a client-supplied price
A26: confirm_order() / reject_order() | B26: Seller accepts or declines | C26: Rejection always fully refunds, regardless of instalment timing
A27: make_instalment_payment() | B27: Each instalment payment is its own wallet hold, not an immediate debit | C27: Nothing is spent until delivery is confirmed
A28: mark_order_delivered() | B28: Finalizes every hold on the order in one clean debit | C28: Physically refuses to run on an instalment order with an outstanding balance
A29: cancel_instalment_order() | B29: The exact tiered refund policy: full refund inside 7 days, 20%-fee partial refund 7-90 days, no refund after | C29: Buyer-initiated only — seller rejection uses the separate, always-full-refund path
A30: DELIVERY DISPATCH
A31: delivery_agents | B31: Zone, online status, verification, total_assignments/total_fulfilled counts | C31: acceptance_rate is a derived view column, not a stored field that could drift out of sync
A32: delivery_assignments | B32: One row per assignment attempt; reassignment supersedes rather than overwrites, preserving history | C32: Partial unique index guarantees only one ACTIVE assignment per order — the actual mechanism preventing riders racing for the same order
A33: auto_assign_order() | B33: Scores online, approved agents by zone match first, acceptance rate as tiebreaker | C33: Wired directly into confirm_order() — assignment happens atomically with confirmation, not as a separate step
A34: escalate_overdue_assignments() | B34: Flags anything past its 10-minute SLA as escalated | C34: Genuinely scheduled via pg_cron, runs every 60 seconds — verified live in cron.job, not just written and hoped for
A35: admin_reassign_order() | B35: Manual override, works whether the prior assignment is still active or already escalated
A36: mark_order_delivered() — corrected | B36: Finalizes the wallet hold and resolves the matching delivery assignment | C36: Caught and fixed a real bug this session: originally only let the SELLER mark delivery complete. Corrected to buyer / assigned agent / seller (pickup orders) / admin.
A39: NATIONAL GEOGRAPHY (built ahead of the neighborhood-level document)
A40: states | B40: All 36 states + FCT, real data sourced and verified against a structured public dataset (not typed from memory) | C40: Only Kaduna has is_launched = true — the actual mechanism for activating Kano/Lagos/Abuja later
A41: local_government_areas | B41: All 774 LGAs nationally, verified count matches official sources exactly | C41: Kaduna's 23 confirmed to match, in the same order, as every form built earlier this project
A42: neighborhood_areas | B42: Structurally ready, deliberately empty | C42: Waiting on the user's local-knowledge document — this level was not guessed at
...
